INTERNALERROR> Traceback (most recent call last):
INTERNALERROR>   File "/Users/wesleyhoang/Desktop/code/cymate-template/web-template/venv/lib/python3.10/site-packages/_pytest/main.py", line 266, in wrap_session
INTERNALERROR>     config._do_configure()
INTERNALERROR>   File "/Users/wesleyhoang/Desktop/code/cymate-template/web-template/venv/lib/python3.10/site-packages/_pytest/config/__init__.py", line 1037, in _do_configure
INTERNALERROR>     self.hook.pytest_configure.call_historic(kwargs=dict(config=self))
INTERNALERROR>   File "/Users/wesleyhoang/Desktop/code/cymate-template/web-template/venv/lib/python3.10/site-packages/pluggy/_hooks.py", line 277, in call_historic
INTERNALERROR>     res = self._hookexec(self.name, self.get_hookimpls(), kwargs, False)
INTERNALERROR>   File "/Users/wesleyhoang/Desktop/code/cymate-template/web-template/venv/lib/python3.10/site-packages/pluggy/_manager.py", line 80, in _hookexec
INTERNALERROR>     return self._inner_hookexec(hook_name, methods, kwargs, firstresult)
INTERNALERROR>   File "/Users/wesleyhoang/Desktop/code/cymate-template/web-template/venv/lib/python3.10/site-packages/pluggy/_callers.py", line 60, in _multicall
INTERNALERROR>     return outcome.get_result()
INTERNALERROR>   File "/Users/wesleyhoang/Desktop/code/cymate-template/web-template/venv/lib/python3.10/site-packages/pluggy/_result.py", line 60, in get_result
INTERNALERROR>     raise ex[1].with_traceback(ex[2])
INTERNALERROR>   File "/Users/wesleyhoang/Desktop/code/cymate-template/web-template/venv/lib/python3.10/site-packages/pluggy/_callers.py", line 39, in _multicall
INTERNALERROR>     res = hook_impl.function(*args)
INTERNALERROR>   File "/Users/wesleyhoang/Desktop/code/cymate-template/web-template/src/main/python/company-template/tests/conftest.py", line 101, in pytest_configure
INTERNALERROR>     logging.basicConfig(
INTERNALERROR>   File "/Library/Frameworks/Python.framework/Versions/3.10/lib/python3.10/logging/__init__.py", line 2031, in basicConfig
INTERNALERROR>     h = FileHandler(filename, mode,
INTERNALERROR>   File "/Library/Frameworks/Python.framework/Versions/3.10/lib/python3.10/logging/__init__.py", line 1167, in __init__
INTERNALERROR>     StreamHandler.__init__(self, self._open())
INTERNALERROR>   File "/Library/Frameworks/Python.framework/Versions/3.10/lib/python3.10/logging/__init__.py", line 1197, in _open
INTERNALERROR>     return open_func(self.baseFilename, self.mode,
INTERNALERROR> OSError: [Errno 30] Read-only file system: '/tests_gw0.log'
INTERNALERROR> Traceback (most recent call last):
INTERNALERROR>   File "/Users/wesleyhoang/Desktop/code/cymate-template/web-template/venv/lib/python3.10/site-packages/_pytest/main.py", line 266, in wrap_session
INTERNALERROR>     config._do_configure()
INTERNALERROR>   File "/Users/wesleyhoang/Desktop/code/cymate-template/web-template/venv/lib/python3.10/site-packages/_pytest/config/__init__.py", line 1037, in _do_configure
INTERNALERROR>     self.hook.pytest_configure.call_historic(kwargs=dict(config=self))
INTERNALERROR>   File "/Users/wesleyhoang/Desktop/code/cymate-template/web-template/venv/lib/python3.10/site-packages/pluggy/_hooks.py", line 277, in call_historic
INTERNALERROR>     res = self._hookexec(self.name, self.get_hookimpls(), kwargs, False)
INTERNALERROR>   File "/Users/wesleyhoang/Desktop/code/cymate-template/web-template/venv/lib/python3.10/site-packages/pluggy/_manager.py", line 80, in _hookexec
INTERNALERROR>     return self._inner_hookexec(hook_name, methods, kwargs, firstresult)
INTERNALERROR>   File "/Users/wesleyhoang/Desktop/code/cymate-template/web-template/venv/lib/python3.10/site-packages/pluggy/_callers.py", line 60, in _multicall
INTERNALERROR>     return outcome.get_result()
INTERNALERROR>   File "/Users/wesleyhoang/Desktop/code/cymate-template/web-template/venv/lib/python3.10/site-packages/pluggy/_result.py", line 60, in get_result
INTERNALERROR>     raise ex[1].with_traceback(ex[2])
INTERNALERROR>   File "/Users/wesleyhoang/Desktop/code/cymate-template/web-template/venv/lib/python3.10/site-packages/pluggy/_callers.py", line 39, in _multicall
INTERNALERROR>     res = hook_impl.function(*args)
INTERNALERROR>   File "/Users/wesleyhoang/Desktop/code/cymate-template/web-template/src/main/python/company-template/tests/conftest.py", line 101, in pytest_configure
INTERNALERROR>     logging.basicConfig(
INTERNALERROR>   File "/Library/Frameworks/Python.framework/Versions/3.10/lib/python3.10/logging/__init__.py", line 2031, in basicConfig
INTERNALERROR>     h = FileHandler(filename, mode,
INTERNALERROR>   File "/Library/Frameworks/Python.framework/Versions/3.10/lib/python3.10/logging/__init__.py", line 1167, in __init__
INTERNALERROR>     StreamHandler.__init__(self, self._open())
INTERNALERROR>   File "/Library/Frameworks/Python.framework/Versions/3.10/lib/python3.10/logging/__init__.py", line 1197, in _open
INTERNALERROR>     return open_func(self.baseFilename, self.mode,
INTERNALERROR> OSError: [Errno 30] Read-only file system: '/tests_gw1.log'
INTERNALERROR> Traceback (most recent call last):
INTERNALERROR>   File "/Users/wesleyhoang/Desktop/code/cymate-template/web-template/venv/lib/python3.10/site-packages/_pytest/main.py", line 266, in wrap_session
INTERNALERROR>     config._do_configure()
INTERNALERROR>   File "/Users/wesleyhoang/Desktop/code/cymate-template/web-template/venv/lib/python3.10/site-packages/_pytest/config/__init__.py", line 1037, in _do_configure
INTERNALERROR>     self.hook.pytest_configure.call_historic(kwargs=dict(config=self))
INTERNALERROR>   File "/Users/wesleyhoang/Desktop/code/cymate-template/web-template/venv/lib/python3.10/site-packages/pluggy/_hooks.py", line 277, in call_historic
INTERNALERROR>     res = self._hookexec(self.name, self.get_hookimpls(), kwargs, False)
INTERNALERROR>   File "/Users/wesleyhoang/Desktop/code/cymate-template/web-template/venv/lib/python3.10/site-packages/pluggy/_manager.py", line 80, in _hookexec
INTERNALERROR>     return self._inner_hookexec(hook_name, methods, kwargs, firstresult)
INTERNALERROR>   File "/Users/wesleyhoang/Desktop/code/cymate-template/web-template/venv/lib/python3.10/site-packages/pluggy/_callers.py", line 60, in _multicall
INTERNALERROR>     return outcome.get_result()
INTERNALERROR>   File "/Users/wesleyhoang/Desktop/code/cymate-template/web-template/venv/lib/python3.10/site-packages/pluggy/_result.py", line 60, in get_result
INTERNALERROR>     raise ex[1].with_traceback(ex[2])
INTERNALERROR>   File "/Users/wesleyhoang/Desktop/code/cymate-template/web-template/venv/lib/python3.10/site-packages/pluggy/_callers.py", line 39, in _multicall
INTERNALERROR>     res = hook_impl.function(*args)
INTERNALERROR>   File "/Users/wesleyhoang/Desktop/code/cymate-template/web-template/src/main/python/company-template/tests/conftest.py", line 101, in pytest_configure
INTERNALERROR>     logging.basicConfig(
INTERNALERROR>   File "/Library/Frameworks/Python.framework/Versions/3.10/lib/python3.10/logging/__init__.py", line 2031, in basicConfig
INTERNALERROR>     h = FileHandler(filename, mode,
INTERNALERROR>   File "/Library/Frameworks/Python.framework/Versions/3.10/lib/python3.10/logging/__init__.py", line 1167, in __init__
INTERNALERROR>     StreamHandler.__init__(self, self._open())
INTERNALERROR>   File "/Library/Frameworks/Python.framework/Versions/3.10/lib/python3.10/logging/__init__.py", line 1197, in _open
INTERNALERROR>     return open_func(self.baseFilename, self.mode,
INTERNALERROR> OSError: [Errno 30] Read-only file system: '/tests_gw2.log'
============================= test session starts ==============================
platform darwin -- Python 3.10.0, pytest-7.2.1, pluggy-1.0.0
rootdir: /Users/wesleyhoang/Desktop/code/cymate-template/web-template
plugins: xdist-3.1.0, html-3.2.0, metadata-2.0.4
gw0 I / gw1 I
INTERNALERROR> def worker_internal_error(self, node, formatted_error):
INTERNALERROR>         """
INTERNALERROR>         pytest_internalerror() was called on the worker.
INTERNALERROR>     
INTERNALERROR>         pytest_internalerror() arguments are an excinfo and an excrepr, which can't
INTERNALERROR>         be serialized, so we go with a poor man's solution of raising an exception
INTERNALERROR>         here ourselves using the formatted message.
INTERNALERROR>         """
INTERNALERROR>         self._active_nodes.remove(node)
INTERNALERROR>         try:
INTERNALERROR> >           assert False, formatted_error
INTERNALERROR> E           AssertionError: Traceback (most recent call last):
INTERNALERROR> E               File "/Users/wesleyhoang/Desktop/code/cymate-template/web-template/venv/lib/python3.10/site-packages/_pytest/main.py", line 266, in wrap_session
INTERNALERROR> E                 config._do_configure()
INTERNALERROR> E               File "/Users/wesleyhoang/Desktop/code/cymate-template/web-template/venv/lib/python3.10/site-packages/_pytest/config/__init__.py", line 1037, in _do_configure
INTERNALERROR> E                 self.hook.pytest_configure.call_historic(kwargs=dict(config=self))
INTERNALERROR> E               File "/Users/wesleyhoang/Desktop/code/cymate-template/web-template/venv/lib/python3.10/site-packages/pluggy/_hooks.py", line 277, in call_historic
INTERNALERROR> E                 res = self._hookexec(self.name, self.get_hookimpls(), kwargs, False)
INTERNALERROR> E               File "/Users/wesleyhoang/Desktop/code/cymate-template/web-template/venv/lib/python3.10/site-packages/pluggy/_manager.py", line 80, in _hookexec
INTERNALERROR> E                 return self._inner_hookexec(hook_name, methods, kwargs, firstresult)
INTERNALERROR> E               File "/Users/wesleyhoang/Desktop/code/cymate-template/web-template/venv/lib/python3.10/site-packages/pluggy/_callers.py", line 60, in _multicall
INTERNALERROR> E                 return outcome.get_result()
INTERNALERROR> E               File "/Users/wesleyhoang/Desktop/code/cymate-template/web-template/venv/lib/python3.10/site-packages/pluggy/_result.py", line 60, in get_result
INTERNALERROR> E                 raise ex[1].with_traceback(ex[2])
INTERNALERROR> E               File "/Users/wesleyhoang/Desktop/code/cymate-template/web-template/venv/lib/python3.10/site-packages/pluggy/_callers.py", line 39, in _multicall
INTERNALERROR> E                 res = hook_impl.function(*args)
INTERNALERROR> E               File "/Users/wesleyhoang/Desktop/code/cymate-template/web-template/src/main/python/company-template/tests/conftest.py", line 101, in pytest_configure
INTERNALERROR> E                 logging.basicConfig(
INTERNALERROR> E               File "/Library/Frameworks/Python.framework/Versions/3.10/lib/python3.10/logging/__init__.py", line 2031, in basicConfig
INTERNALERROR> E                 h = FileHandler(filename, mode,
INTERNALERROR> E               File "/Library/Frameworks/Python.framework/Versions/3.10/lib/python3.10/logging/__init__.py", line 1167, in __init__
INTERNALERROR> E                 StreamHandler.__init__(self, self._open())
INTERNALERROR> E               File "/Library/Frameworks/Python.framework/Versions/3.10/lib/python3.10/logging/__init__.py", line 1197, in _open
INTERNALERROR> E                 return open_func(self.baseFilename, self.mode,
INTERNALERROR> E             OSError: [Errno 30] Read-only file system: '/tests_gw0.log'
INTERNALERROR> E           assert False
INTERNALERROR> 
INTERNALERROR> venv/lib/python3.10/site-packages/xdist/dsession.py:190: AssertionError
[gw0] node down: Not properly terminated

replacing crashed worker gw0
[gw2] darwin Python 3.10.0 cwd: /Users/wesleyhoang/Desktop/code/cymate-template/web-template
INTERNALERROR> Traceback (most recent call last):
INTERNALERROR>   File "/Users/wesleyhoang/Desktop/code/cymate-template/web-template/venv/lib/python3.10/site-packages/_pytest/main.py", line 270, in wrap_session
INTERNALERROR>     session.exitstatus = doit(config, session) or 0
INTERNALERROR>   File "/Users/wesleyhoang/Desktop/code/cymate-template/web-template/venv/lib/python3.10/site-packages/_pytest/main.py", line 324, in _main
INTERNALERROR>     config.hook.pytest_runtestloop(session=session)
INTERNALERROR>   File "/Users/wesleyhoang/Desktop/code/cymate-template/web-template/venv/lib/python3.10/site-packages/pluggy/_hooks.py", line 265, in __call__
INTERNALERROR>     return self._hookexec(self.name, self.get_hookimpls(), kwargs, firstresult)
INTERNALERROR>   File "/Users/wesleyhoang/Desktop/code/cymate-template/web-template/venv/lib/python3.10/site-packages/pluggy/_manager.py", line 80, in _hookexec
INTERNALERROR>     return self._inner_hookexec(hook_name, methods, kwargs, firstresult)
INTERNALERROR>   File "/Users/wesleyhoang/Desktop/code/cymate-template/web-template/venv/lib/python3.10/site-packages/pluggy/_callers.py", line 60, in _multicall
INTERNALERROR>     return outcome.get_result()
INTERNALERROR>   File "/Users/wesleyhoang/Desktop/code/cymate-template/web-template/venv/lib/python3.10/site-packages/pluggy/_result.py", line 60, in get_result
INTERNALERROR>     raise ex[1].with_traceback(ex[2])
INTERNALERROR>   File "/Users/wesleyhoang/Desktop/code/cymate-template/web-template/venv/lib/python3.10/site-packages/pluggy/_callers.py", line 39, in _multicall
INTERNALERROR>     res = hook_impl.function(*args)
INTERNALERROR>   File "/Users/wesleyhoang/Desktop/code/cymate-template/web-template/venv/lib/python3.10/site-packages/xdist/dsession.py", line 115, in pytest_runtestloop
INTERNALERROR>     self.loop_once()
INTERNALERROR>   File "/Users/wesleyhoang/Desktop/code/cymate-template/web-template/venv/lib/python3.10/site-packages/xdist/dsession.py", line 138, in loop_once
INTERNALERROR>     call(**kwargs)
INTERNALERROR>   File "/Users/wesleyhoang/Desktop/code/cymate-template/web-template/venv/lib/python3.10/site-packages/xdist/dsession.py", line 228, in worker_errordown
INTERNALERROR>     self._active_nodes.remove(node)
INTERNALERROR> KeyError: <WorkerController gw0>

============================ no tests ran in 0.75s =============================
